Workbook

Sheet Read me
A1: UX Health Check - Criteria Library
A2: v1.51 - 24 October 2026 - for NZ Government agencies (see the Version tab for change history)
A4: Purpose
A5: What this is | B5: A library of self-assessment criteria for a 'UX health check' of a website or application, covering accessibility, usability, content, brand, security and privacy, reliability and service levels, support, legal obligations, content management and measurement. Each row is designed to become one question in the app, with its scoring weight, report recommendation and source.
A6: Intended use | B6: Source of truth for the app's question bank and scoring. The 'Criteria (simple)' tab is the proposed basis for the app; the full 'Criteria' tab is the detailed reference set. Export either to CSV or JSON to seed the app.
A7: Status | B7: Released as v1.00 for review and piloting. Weights, critical flags and wording should be validated with practitioners (accessibility, security, service owners) and tested on 2-3 real services before formal use.
A9: Tabs
A10: Criteria | B10: Detailed set: 96 criteria. Columns A-N are the library. Columns P-V are a test harness: enter answers in the yellow Test answer column to see how the scoring behaves. Columns W-X hold a short-labelled supporting link for each criterion, shown with its recommendation in the report.
A11: Scoring | B11: Scoring for the detailed set: parameters, category weights out of 100, overall score, critical-failure cap, rating band and the top 5 key recommendations.
A12: Criteria (simple) | B12: Simple set: only the criteria with weight 3 (the highest-importance criteria) - 19 questions across all 10 categories. Shows only the question, category, critical flag, recommendation, source, NZ status and applicability - no evidence prompts or weights. Text is pulled live from the Criteria tab by ID, so wording edits flow through. Answer in the yellow Answer column.
A13: Scoring (simple) | B13: Scores the simple set out of 100, using the same method as the detailed set. Its parameters and category points are separate, so the simple model can be tuned without affecting the detailed one.
A14: Materiality | B14: Separate assessment of how much the application matters - to its users and to the organisation - on a 5-point scale (1 Immaterial to 5 Critical), from 10 factor questions. It is not part of the UX health score and is reported separately.
A15: Service tiers | B15: Proposed service tier definitions (Platinum, Gold, Silver, Bronze) with availability, support, incident, recovery, monitoring and health check expectations. The suggested tier follows from the materiality rating.
A16: Report (simple) | B16: Preview of the output report for the simple set: UX health score and rating, materiality rating and service tier shown separately, key recommendations and category results. The app's report should follow this layout.
A17: Sources | B17: Every standard, law, guide and tool referenced, with version/status, a live link checked on 24 October 2026, how the link was checked, and licence notes for reusing wording.
A18: Version | B18: Version history. Each release has one row recording what changed, how the framework was developed and why.
A20: Editing legend
A21: Yellow cells | B21: Inputs you can change - answers, answer point values, critical cap, rating thresholds, category points.
A22: Grey cells | B22: Formulas - do not overwrite.
A23: Sample answers | B23: The answer columns on both criteria tabs are pre-filled with illustrative sample answers so the scoring can be seen working. They do not describe any real service. Clear or replace them.
A24: Simple set membership | B24: The 13 rows in Criteria (simple) were selected because their weight is 3. If you change a weight on the Criteria tab, add or remove the matching ID on Criteria (simple) by hand - membership is not automatic.
A26: Criteria columns
A27: ID | B27: Stable key for the app (category prefix + number). Don't reuse IDs for different criteria.
A28: Category / Sub-category | B28: Ten categories (see Scoring tab) with sub-categories for grouping in the report.
A29: Question | B29: Worded for a self-assessor. Answered Yes / Partial / No / N/A.
A30: Evidence prompt | B30: What the assessor should be able to show (detailed set only).
A31: Weight (1-3) | B31: Relative importance within its category: 3 = high, 2 = medium, 1 = low. Weight 3 rows form the simple set.
A32: Critical (Y/N) | B32: A 'No' on any critical criterion caps the overall score. Partial does not trigger the cap.
A33: Recommendation | B33: Text shown in the report when the answer is Partial or No.
A34: Source / Source version | B34: Where the criterion comes from, so it can be updated when the source changes.
A35: NZ status | B35: Mandatory (NZ) = required by NZ law or an all-of-government standard for mandated organisations. Recommended (NZ) = NZ Government guidance, draft standards or expected practice. Good practice = international practice with no NZ mandate.
A36: Applies to | B36: All, Public-facing, Transactional, Authenticated, Uses media, Uses CMS, Uses AI. The app can use this to hide irrelevant questions; otherwise answer N/A.
A37: Review notes | B37: Known upcoming changes, licence cautions and interpretation notes.
A39: Scoring model (both sets)
A40: Answer points | B40: Yes = 1, Partial = 0.5, No = 0. N/A and blank answers are excluded from both earned and available points.
A41: Category score | B41: (points earned) / (points available) x category points. Categories with no applicable answers are excluded and the rest are rescaled to 100.
A42: Overall score | B42: Sum of category scores, out of 100. If any critical criterion is answered No, the overall score is capped (default 60).
A43: Points lost | B43: For each Partial or No, the points it cost the overall score. Used to rank key recommendations (critical failures always rank first).
A45: Important caveats
A46: Changing NZ standards | B46: The Web Accessibility Standard 1.2 (WCAG 2.2 AA) is expected to be replaced by the Digital Accessibility Standard (based on EN 301 549) in early 2027. The Digital Service Design Standard is being refreshed, and Web Usability Standard requirements are expected to become guidance within it. A bill to repeal the Plain Language Act 2022 was before Parliament at the time of release. Affected rows are flagged in Review notes.
...

Sheet Criteria
A1: ID | B1: Category | C1: Sub-category | D1: Question | E1: Answer type | F1: Evidence prompt | G1: Weight (1-3) | H1: Critical (Y/N) | I1: Recommendation (shown if Partial/No) | J1: Source | K1: Source version | L1: NZ status | M1: Applies to | N1: Review notes | P1: Test answer | Q1: Answer points | R1: Weighted earned | S1: Weighted available | T1: Report recommendation | U1: Points lost | V1: Rank key | W1: Supporting link label | X1: Supporting link
A2: ACC-01 | B2: Accessibility | C2: Conformance | D2: Has the service been assessed against WCAG 2.2 Level AA in the last 12 months, including manual testing (not automated tools alone)? | E2: Yes / Partial / No / N/A | F2: Dated accessibility audit report covering the service's key pages and complete processes, with manual test results. | G2: 3 | H2: Y | I2: Commission or complete a WCAG 2.2 AA assessment that includes manual and assistive technology testing, covering every page in each complete process, and repeat it at least annually or after major change. | J2: NZ Government Web Accessibility Standard; WCAG 2.2 | K2: WAS 1.2 (from 17 Mar 2025); WCAG 2.2 AA | L2: Mandatory (NZ) | M2: All | N2: Draft Digital Accessibility Standard (DAS), based on EN 301 549, expected to replace WAS in early 2027. Review wording when DAS is final. | P2: Yes | Q2: =IF(P2="Yes",Scoring!$C$6,IF(P2="Partial",Scoring!$C$7,IF(P2="No",Scoring!$C$8,""))) -> 1 | R2: =IF(Q2="",0,G2*Q2) -> 3 | S2: =IF(Q2="",0,G2) -> 3 | T2: =IF(OR(P2="Partial",P2="No"),I2,"") | U2: =IF(Q2="",0,(1-Q2)*G2/SUMIFS($S$2:$S$97,$B$2:$B$97,B2)*INDEX(Scoring!$C$18:$C$27,MATCH(B2,Scoring!$B$18:$B$27,0))) -> 0 | V2: =IF(U2>0,U2+IF(AND(H2="Y",P2="No"),1000,0)+ROW()/100000,0) -> 0 | W2: NZ Web Accessibility Standard 1.2 | X2: https://www.digital.govt.nz/standards-and-guidance/nz-government-web-standards/web-accessibility-standard-1-2
A3: ACC-02 | B3: Accessibility | C3: Assistive technology | D3: Have the service's key tasks been tested end to end with screen readers on both desktop and mobile (for example NVDA or JAWS, VoiceOver, TalkBack)? | E3: Yes / Partial / No / N/A | F3: Test scripts and results per screen reader/browser combination, dated, with issues logged. | G3: 3 | H3: N | I3: Test every key task with at least one desktop and one mobile screen reader, ideally including blind and low vision users, and fix issues that stop tasks being completed. | J3: WCAG 2.2 SC 4.1.2, 1.3.1; W3C WCAG-EM | K3: WCAG 2.2; WCAG-EM 2.0 (Jul 2026) | L3: Recommended (NZ) | M3: All | P3: Yes | Q3: =IF(P3="Yes",Scoring!$C$6,IF(P3="Partial",Scoring!$C$7,IF(P3="No",Scoring!$C$8,""))) -> 1 | R3: =IF(Q3="",0,G3*Q3) -> 3 | S3: =IF(Q3="",0,G3) -> 3 | T3: =IF(OR(P3="Partial",P3="No"),I3,"") | U3: =IF(Q3="",0,(1-Q3)*G3/SUMIFS($S$2:$S$97,$B$2:$B$97,B3)*INDEX(Scoring!$C$18:$C$27,MATCH(B3,Scoring!$B$18:$B$27,0))) -> 0 | V3: =IF(U3>0,U3+IF(AND(H3="Y",P3="No"),1000,0)+ROW()/100000,0) -> 0 | W3: W3C accessibility evaluation methodology | X3: https://www.w3.org/WAI/test-evaluate/conformance/wcag-em/
A4: ACC-03 | B4: Accessibility | C4: Perceivable | D4: Do all images, icons, charts and other non-text content have appropriate text alternatives (or are marked as decorative)? | E4: Yes / Partial / No / N/A | F4: Audit findings for SC 1.1.1; content guidance requiring alt text; CMS alt text field usage. | G4: 2 | H4: N | I4: Provide meaningful text alternatives for informative images, icons and charts, mark decorative images so screen readers skip them, and provide data tables for complex charts. | J4: WCAG 2.2 SC 1.1.1 | K4: WCAG 2.2 A | L4: Mandatory (NZ) | M4: All | P4: Partial | Q4: =IF(P4="Yes",Scoring!$C$6,IF(P4="Partial",Scoring!$C$7,IF(P4="No",Scoring!$C$8,""))) -> 0.5 | R4: =IF(Q4="",0,G4*Q4) -> 1 | S4: =IF(Q4="",0,G4) -> 2 | T4: =IF(OR(P4="Partial",P4="No"),I4,"") -> Provide meaningful text alternatives for informative images, icons and charts, mark decorative images so screen readers skip them, and provide data tables for complex charts. | U4: =IF(Q4="",0,(1-Q4)*G4/SUMIFS($S$2:$S$97,$B$2:$B$97,B4)*INDEX(Scoring!$C$18:$C$27,MATCH(B4,Scoring!$B$18:$B$27,0))) -> 0.60606061 | V4: =IF(U4>0,U4+IF(AND(H4="Y",P4="No"),1000,0)+ROW()/100000,0) -> 0.60610061 | W4: WCAG 2.2 quick reference | X4: https://www.w3.org/WAI/WCAG22/quickref/
A5: ACC-04 | B5: Accessibility | C5: Perceivable | D5: Is page structure conveyed programmatically - meaningful page titles, headings, landmarks, lists, table headers and form labels? | E5: Yes / Partial / No / N/A | F5: Audit findings for SC 1.3.1, 2.4.2, 2.4.6; screen reader heading/landmark navigation test. | G5: 2 | H5: N | I5: Use semantic HTML (headings, landmarks, lists, labelled controls) and unique, descriptive page titles so screen reader users can understand and navigate the structure. | J5: WCAG 2.2 SC 1.3.1, 2.4.2, 2.4.6 | K5: WCAG 2.2 A/AA | L5: Mandatory (NZ) | M5: All | P5: Yes | Q5: =IF(P5="Yes",Scoring!$C$6,IF(P5="Partial",Scoring!$C$7,IF(P5="No",Scoring!$C$8,""))) -> 1 | R5: =IF(Q5="",0,G5*Q5) -> 2 | S5: =IF(Q5="",0,G5) -> 2 | T5: =IF(OR(P5="Partial",P5="No"),I5,"") | U5: =IF(Q5="",0,(1-Q5)*G5/SUMIFS($S$2:$S$97,$B$2:$B$97,B5)*INDEX(Scoring!$C$18:$C$27,MATCH(B5,Scoring!$B$18:$B$27,0))) -> 0 | V5: =IF(U5>0,U5+IF(AND(H5="Y",P5="No"),1000,0)+ROW()/100000,0) -> 0 | W5: WCAG 2.2 quick reference | X5: https://www.w3.org/WAI/WCAG22/quickref/
A6: ACC-05 | B6: Accessibility | C6: Operable | D6: Can every function be used with a keyboard alone, with no keyboard traps, a logical focus order, and a visible focus indicator that is not hidden by other content? | E6: Yes / Partial / No / N/A | F6: Keyboard-only test of each key task; audit findings for SC 2.1.1, 2.1.2, 2.4.3, 2.4.7, 2.4.11. | G6: 3 | H6: Y | I6: Make all functionality keyboard operable, remove keyboard traps, keep focus order logical and ensure the focus indicator is always visible and not obscured by sticky headers, banners or overlays. | J6: WCAG 2.2 SC 2.1.1, 2.1.2, 2.4.3, 2.4.7, 2.4.11 | K6: WCAG 2.2 A/AA | L6: Mandatory (NZ) | M6: All | P6: Partial | Q6: =IF(P6="Yes",Scoring!$C$6,IF(P6="Partial",Scoring!$C$7,IF(P6="No",Scoring!$C$8,""))) -> 0.5 | R6: =IF(Q6="",0,G6*Q6) -> 1.5 | S6: =IF(Q6="",0,G6) -> 3 | T6: =IF(OR(P6="Partial",P6="No"),I6,"") -> Make all functionality keyboard operable, remove keyboard traps, keep focus order logical and ensure the focus indicator is always visible and not obscured by sticky headers, banners or overlays. | U6: =IF(Q6="",0,(1-Q6)*G6/SUMIFS($S$2:$S$97,$B$2:$B$97,B6)*INDEX(Scoring!$C$18:$C$27,MATCH(B6,Scoring!$B$18:$B$27,0))) -> 0.90909091 | V6: =IF(U6>0,U6+IF(AND(H6="Y",P6="No"),1000,0)+ROW()/100000,0) -> 0.90915091 | W6: WCAG 2.2 quick reference | X6: https://www.w3.org/WAI/WCAG22/quickref/
A7: ACC-06 | B7: Accessibility | C7: Low vision | D7: Do text, icons, form borders and focus indicators meet WCAG contrast ratios (4.5:1 for normal text, 3:1 for large text and non-text elements)? | E7: Yes / Partial / No / N/A | F7: Contrast check results for brand palette and UI components; audit findings for SC 1.4.3 and 1.4.11. | G7: 2 | H7: N | I7: Check all text and interface components against WCAG contrast ratios and adjust colour tokens in the design system so every combination in use passes. | J7: WCAG 2.2 SC 1.4.3, 1.4.11 | K7: WCAG 2.2 AA | L7: Mandatory (NZ) | M7: All | P7: Yes | Q7: =IF(P7="Yes",Scoring!$C$6,IF(P7="Partial",Scoring!$C$7,IF(P7="No",Scoring!$C$8,""))) -> 1 | R7: =IF(Q7="",0,G7*Q7) -> 2 | S7: =IF(Q7="",0,G7) -> 2 | T7: =IF(OR(P7="Partial",P7="No"),I7,"") | U7: =IF(Q7="",0,(1-Q7)*G7/SUMIFS($S$2:$S$97,$B$2:$B$97,B7)*INDEX(Scoring!$C$18:$C$27,MATCH(B7,Scoring!$B$18:$B$27,0))) -> 0 | V7: =IF(U7>0,U7+IF(AND(H7="Y",P7="No"),1000,0)+ROW()/100000,0) -> 0 | W7: WCAG 2.2 quick reference | X7: https://www.w3.org/WAI/WCAG22/quickref/
A8: ACC-07 | B8: Accessibility | C8: Low vision | D8: Does content remain usable when text is resized to 200% and when zoomed to 400% (320 CSS pixels wide) without loss of content or horizontal scrolling? | E8: Yes / Partial / No / N/A | F8: Zoom and reflow test results on key pages; audit findings for SC 1.4.4, 1.4.10, 1.4.12. | G8: 2 | H8: N | I8: Use responsive layouts and relative units so content reflows at 400% zoom and text spacing can be increased without content being cut off or overlapping. | J8: WCAG 2.2 SC 1.4.4, 1.4.10, 1.4.12 | K8: WCAG 2.2 AA | L8: Mandatory (NZ) | M8: All | P8: Partial | Q8: =IF(P8="Yes",Scoring!$C$6,IF(P8="Partial",Scoring!$C$7,IF(P8="No",Scoring!$C$8,""))) -> 0.5 | R8: =IF(Q8="",0,G8*Q8) -> 1 | S8: =IF(Q8="",0,G8) -> 2 | T8: =IF(OR(P8="Partial",P8="No"),I8,"") -> Use responsive layouts and relative units so content reflows at 400% zoom and text spacing can be increased without content being cut off or overlapping. | U8: =IF(Q8="",0,(1-Q8)*G8/SUMIFS($S$2:$S$97,$B$2:$B$97,B8)*INDEX(Scoring!$C$18:$C$27,MATCH(B8,Scoring!$B$18:$B$27,0))) -> 0.60606061 | V8: =IF(U8>0,U8+IF(AND(H8="Y",P8="No"),1000,0)+ROW()/100000,0) -> 0.60614061 | W8: WCAG 2.2 quick reference | X8: https://www.w3.org/WAI/WCAG22/quickref/
A9: ACC-08 | B9: Accessibility | C9: Perceivable | D9: Is information never conveyed by colour alone (for example error states, required fields, chart series, status indicators)? | E9: Yes / Partial / No / N/A | F9: Audit findings for SC 1.4.1; review of status and error patterns. | G9: 1 | H9: N | I9: Pair colour with text, icons or patterns so information is still available to people who cannot perceive colour differences. | J9: WCAG 2.2 SC 1.4.1 | K9: WCAG 2.2 A | L9: Mandatory (NZ) | M9: All | P9: Yes | Q9: =IF(P9="Yes",Scoring!$C$6,IF(P9="Partial",Scoring!$C$7,IF(P9="No",Scoring!$C$8,""))) -> 1 | R9: =IF(Q9="",0,G9*Q9) -> 1 | S9: =IF(Q9="",0,G9) -> 1 | T9: =IF(OR(P9="Partial",P9="No"),I9,"") | U9: =IF(Q9="",0,(1-Q9)*G9/SUMIFS($S$2:$S$97,$B$2:$B$97,B9)*INDEX(Scoring!$C$18:$C$27,MATCH(B9,Scoring!$B$18:$B$27,0))) -> 0 | V9: =IF(U9>0,U9+IF(AND(H9="Y",P9="No"),1000,0)+ROW()/100000,0) -> 0 | W9: WCAG 2.2 quick reference | X9: https://www.w3.org/WAI/WCAG22/quickref/
A10: ACC-09 | B10: Accessibility | C10: Forms | D10: Do forms have visible labels and instructions, identify errors in text, suggest corrections, and announce status messages to assistive technology? | E10: Yes / Partial / No / N/A | F10: Audit findings for SC 3.3.1, 3.3.2, 3.3.3, 4.1.3; screen reader test of form errors. | G10: 2 | H10: N | I10: Give every field a visible label and clear instructions, describe errors in text next to the field and in a summary, suggest how to fix them, and announce status changes to screen readers. | J10: WCAG 2.2 SC 3.3.1, 3.3.2, 3.3.3, 4.1.3 | K10: WCAG 2.2 A/AA | L10: Mandatory (NZ) | M10: Transactional | P10: Yes | Q10: =IF(P10="Yes",Scoring!$C$6,IF(P10="Partial",Scoring!$C$7,IF(P10="No",Scoring!$C$8,""))) -> 1 | R10: =IF(Q10="",0,G10*Q10) -> 2 | S10: =IF(Q10="",0,G10) -> 2 | T10: =IF(OR(P10="Partial",P10="No"),I10,"") | U10: =IF(Q10="",0,(1-Q10)*G10/SUMIFS($S$2:$S$97,$B$2:$B$97,B10)*INDEX(Scoring!$C$18:$C$27,MATCH(B10,Scoring!$B$18:$B$27,0))) -> 0 | V10: =IF(U10>0,U10+IF(AND(H10="Y",P10="No"),1000,0)+ROW()/100000,0) -> 0 | W10: WCAG 2.2 quick reference | X10: https://www.w3.org/WAI/WCAG22/quickref/
A11: ACC-10 | B11: Accessibility | C11: Forms | D11: Does sign-in avoid cognitive function tests (such as remembering or transcribing codes without paste or password manager support), and does the service avoid asking for the same information twice? | E11: Yes / Partial / No / N/A | F11: Audit findings for SC 3.3.7 and 3.3.8 (new in WCAG 2.2); sign-in flow review. | G11: 2 | H11: N | I11: Allow paste and password managers, offer alternatives to puzzles or memory tests at sign-in, and auto-fill or let users select information they have already given. | J11: WCAG 2.2 SC 3.3.7, 3.3.8 | K11: WCAG 2.2 A/AA | L11: Mandatory (NZ) | M11: Authenticated | P11: Partial | Q11: =IF(P11="Yes",Scoring!$C$6,IF(P11="Partial",Scoring!$C$7,IF(P11="No",Scoring!$C$8,""))) -> 0.5 | R11: =IF(Q11="",0,G11*Q11) -> 1 | S11: =IF(Q11="",0,G11) -> 2 | T11: =IF(OR(P11="Partial",P11="No"),I11,"") -> Allow paste and password managers, offer alternatives to puzzles or memory tests at sign-in, and auto-fill or let users select information they have already given. | U11: =IF(Q11="",0,(1-Q11)*G11/SUMIFS($S$2:$S$97,$B$2:$B$97,B11)*INDEX(Scoring!$C$18:$C$27,MATCH(B11,Scoring!$B$18:$B$27,0))) -> 0.60606061 | V11: =IF(U11>0,U11+IF(AND(H11="Y",P11="No"),1000,0)+ROW()/100000,0) -> 0.60617061 | W11: WCAG 2.2 quick reference | X11: https://www.w3.org/WAI/WCAG22/quickref/
A12: ACC-11 | B12: Accessibility | C12: Mobile | D12: Are touch targets large enough (at least 24 by 24 CSS pixels or adequately spaced), and can actions that use dragging or multi-point gestures also be done with a single tap? | E12: Yes / Partial / No / N/A | F12: Audit findings for SC 2.5.7, 2.5.8; mobile device testing. | G12: 1 | H12: N | I12: Size and space interactive targets to at least 24 by 24 CSS pixels and provide single-pointer alternatives for drag and gesture interactions. | J12: WCAG 2.2 SC 2.5.7, 2.5.8 | K12: WCAG 2.2 AA | L12: Mandatory (NZ) | M12: All | P12: Yes | Q12: =IF(P12="Yes",Scoring!$C$6,IF(P12="Partial",Scoring!$C$7,IF(P12="No",Scoring!$C$8,""))) -> 1 | R12: =IF(Q12="",0,G12*Q12) -> 1 | S12: =IF(Q12="",0,G12) -> 1 | T12: =IF(OR(P12="Partial",P12="No"),I12,"") | U12: =IF(Q12="",0,(1-Q12)*G12/SUMIFS($S$2:$S$97,$B$2:$B$97,B12)*INDEX(Scoring!$C$18:$C$27,MATCH(B12,Scoring!$B$18:$B$27,0))) -> 0 | V12: =IF(U12>0,U12+IF(AND(H12="Y",P12="No"),1000,0)+ROW()/100000,0) -> 0 | W12: WCAG 2.2 quick reference | X12: https://www.w3.org/WAI/WCAG22/quickref/
A13: ACC-12 | B13: Accessibility | C13: Media | D13: Do videos and audio have captions, transcripts and (where needed) audio description? | E13: Yes / Partial / No / N/A | F13: Media inventory showing captions, transcripts and audio description status. | G13: 1 | H13: N | I13: Provide captions and transcripts for all prerecorded media and audio description where visual information is not otherwise conveyed, noting the specific exceptions in the Web Accessibility Standard. | J13: WCAG 2.2 SC 1.2.1, 1.2.2, 1.2.5; WAS 1.2 exceptions | K13: WCAG 2.2 A/AA; WAS 1.2 | L13: Mandatory (NZ) | M13: Uses media | N13: WAS 1.2 modifies some media requirements (e.g. live captions, audio description). Check current exceptions. | P13: Partial | Q13: =IF(P13="Yes",Scoring!$C$6,IF(P13="Partial",Scoring!$C$7,IF(P13="No",Scoring!$C$8,""))) -> 0.5 | R13: =IF(Q13="",0,G13*Q13) -> 0.5 | S13: =IF(Q13="",0,G13) -> 1 | T13: =IF(OR(P13="Partial",P13="No"),I13,"") -> Provide captions and transcripts for all prerecorded media and audio description where visual information is not otherwise conveyed, noting the specific exceptions in the Web Accessibility Standard. | U13: =IF(Q13="",0,(1-Q13)*G13/SUMIFS($S$2:$S$97,$B$2:$B$97,B13)*INDEX(Scoring!$C$18:$C$27,MATCH(B13,Scoring!$B$18:$B$27,0))) -> 0.3030303 | V13: =IF(U13>0,U13+IF(AND(H13="Y",P13="No"),1000,0)+ROW()/100000,0) -> 0.3031603 | W13: WCAG 2.2 quick reference | X13: https://www.w3.org/WAI/WCAG22/quickref/
A14: ACC-13 | B14: Accessibility | C14: Documents | D14: Are PDFs, Word and other documents published by the service accessible, or accompanied by an accessible HTML alternative? | E14: Yes / Partial / No / N/A | F14: Document inventory with accessibility status; publishing guidance. | G14: 2 | H14: N | I14: Publish key content as HTML first; where documents are needed, make them accessible (tagged, structured, with alt text) or provide an accessible alternative. | J14: NZ Government Web Accessibility Guide (accessibility-supported technologies); draft DAS | K14: WAS 1.2; DAS draft (Jul 2026) | L14: Mandatory (NZ) | M14: All | N14: Draft DAS extends scope beyond websites to documents, emails and mobile apps. | P14: Yes | Q14: =IF(P14="Yes",Scoring!$C$6,IF(P14="Partial",Scoring!$C$7,IF(P14="No",Scoring!$C$8,""))) -> 1 | R14: =IF(Q14="",0,G14*Q14) -> 2 | S14: =IF(Q14="",0,G14) -> 2 | T14: =IF(OR(P14="Partial",P14="No"),I14,"") | U14: =IF(Q14="",0,(1-Q14)*G14/SUMIFS($S$2:$S$97,$B$2:$B$97,B14)*INDEX(Scoring!$C$18:$C$27,MATCH(B14,Scoring!$B$18:$B$27,0))) -> 0 | V14: =IF(U14>0,U14+IF(AND(H14="Y",P14="No"),1000,0)+ROW()/100000,0) -> 0 | W14: NZ Digital Accessibility Standard (draft) | X14: https://www.digital.govt.nz/standards-and-guidance/nz-government-web-standards/digital-accessibility-standard
A15: ACC-14 | B15: Accessibility | C15: Process | D15: Is automated accessibility testing built into the design, build and release process (for example axe-core, Pa11y or CWAC) so detectable errors are caught before release? | E15: Yes / Partial / No / N/A | F15: CI/CD configuration or test reports; CWAC scan results for the service. | G15: 2 | H15: N | I15: Add automated accessibility checks to the build pipeline and content publishing workflow, and treat new automatically detectable errors as release blockers. | J15: GCDO guidance on CWAC and automated testing | K15: CWAC (open source) | L15: Recommended (NZ) | M15: All | N15: Automated tests detect only a subset of WCAG issues; never use as the sole evidence for ACC-01. CWAC is open source (GPL-3.0). | P15: Yes | Q15: =IF(P15="Yes",Scoring!$C$6,IF(P15="Partial",Scoring!$C$7,IF(P15="No",Scoring!$C$8,""))) -> 1 | R15: =IF(Q15="",0,G15*Q15) -> 2 | S15: =IF(Q15="",0,G15) -> 2 | T15: =IF(OR(P15="Partial",P15="No"),I15,"") | U15: =IF(Q15="",0,(1-Q15)*G15/SUMIFS($S$2:$S$97,$B$2:$B$97,B15)*INDEX(Scoring!$C$18:$C$27,MATCH(B15,Scoring!$B$18:$B$27,0))) -> 0 | V15: =IF(U15>0,U15+IF(AND(H15="Y",P15="No"),1000,0)+ROW()/100000,0) -> 0 | W15: CWAC accessibility checker (GitHub) | X15: https://github.com/GOVTNZ/cwac
A16: ACC-15 | B16: Accessibility | C16: Reporting | D16: Is there a published accessibility statement giving conformance status, known issues, alternatives and how to report a problem, and a risk assessment and management plan for any non-conformance? | E16: Yes / Partial / No / N/A | F16: Accessibility statement URL; risk assessment and management plan. | G16: 2 | H16: N | I16: Publish and maintain an accessibility statement, and document a risk assessment and management plan for any areas that do not yet conform, with dates for fixes. | J16: Web Accessibility Standard 1.2 s4 (assessment and reporting, incl. risk assessment and management plan) | K16: WAS 1.2 | L16: Mandatory (NZ) | M16: Public-facing | P16: Yes | Q16: =IF(P16="Yes",Scoring!$C$6,IF(P16="Partial",Scoring!$C$7,IF(P16="No",Scoring!$C$8,""))) -> 1 | R16: =IF(Q16="",0,G16*Q16) -> 2 | S16: =IF(Q16="",0,G16) -> 2 | T16: =IF(OR(P16="Partial",P16="No"),I16,"") | U16: =IF(Q16="",0,(1-Q16)*G16/SUMIFS($S$2:$S$97,$B$2:$B$97,B16)*INDEX(Scoring!$C$18:$C$27,MATCH(B16,Scoring!$B$18:$B$27,0))) -> 0 | V16: =IF(U16>0,U16+IF(AND(H16="Y",P16="No"),1000,0)+ROW()/100000,0) -> 0 | W16: NZ Web Accessibility Standard 1.2 | X16: https://www.digital.govt.nz/standards-and-guidance/nz-government-web-standards/web-accessibility-standard-1-2
A17: ACC-16 | B17: Accessibility | C17: Inclusion | D17: Have disabled people (including blind and low vision users) been included in user research and usability testing for this service? | E17: Yes / Partial / No / N/A | F17: Research plans and participant summaries showing disabled participants and assistive technology used. | G17: 2 | H17: N | I17: Recruit disabled people, including assistive technology users, into research and usability testing at each major stage of design and change. | J17: Digital Service Design Standard; AU Digital Service Standard 2.0 criterion 3 (leave no one behind) | K17: DSDS 2018 (refresh underway); AU DSS 2.0 | L17: Recommended (NZ) | M17: All | P17: Partial | Q17: =IF(P17="Yes",Scoring!$C$6,IF(P17="Partial",Scoring!$C$7,IF(P17="No",Scoring!$C$8,""))) -> 0.5 | R17: =IF(Q17="",0,G17*Q17) -> 1 | S17: =IF(Q17="",0,G17) -> 2 | T17: =IF(OR(P17="Partial",P17="No"),I17,"") -> Recruit disabled people, including assistive technology users, into research and usability testing at each major stage of design and change. | U17: =IF(Q17="",0,(1-Q17)*G17/SUMIFS($S$2:$S$97,$B$2:$B$97,B17)*INDEX(Scoring!$C$18:$C$27,MATCH(B17,Scoring!$B$18:$B$27,0))) -> 0.60606061 | V17: =IF(U17>0,U17+IF(AND(H17="Y",P17="No"),1000,0)+ROW()/100000,0) -> 0.60623061 | W17: GOV.UK: making services more inclusive | X17: https://www.gov.uk/service-manual/design/making-your-service-more-inclusive
A18: ACC-17 | B18: Accessibility | C18: Maturity | D18: Does the organisation have accessibility roles, training, and accessibility requirements in procurement and vendor contracts that apply to this service? | E18: Yes / Partial / No / N/A | F18: Role descriptions, training records, contract clauses requiring WCAG 2.2 AA. | G18: 1 | H18: N | I18: Assign accessibility accountability, train designers, developers and content authors, and include accessibility conformance requirements and acceptance testing in vendor contracts. | J18: W3C Accessibility Maturity Model | K18: W3C Group Note (Nov 2025) | L18: Good practice | M18: All | P18: Yes | Q18: =IF(P18="Yes",Scoring!$C$6,IF(P18="Partial",Scoring!$C$7,IF(P18="No",Scoring!$C$8,""))) -> 1 | R18: =IF(Q18="",0,G18*Q18) -> 1 | S18: =IF(Q18="",0,G18) -> 1 | T18: =IF(OR(P18="Partial",P18="No"),I18,"") | U18: =IF(Q18="",0,(1-Q18)*G18/SUMIFS($S$2:$S$97,$B$2:$B$97,B18)*INDEX(Scoring!$C$18:$C$27,MATCH(B18,Scoring!$B$18:$B$27,0))) -> 0 | V18: =IF(U18>0,U18+IF(AND(H18="Y",P18="No"),1000,0)+ROW()/100000,0) -> 0 | W18: W3C Accessibility Maturity Model | X18: https://www.w3.org/TR/maturity-model/
A19: UXD-01 | B19: Usability and design | C19: Responsive design | D19: Is the service responsive or adaptive, so content and controls scale and reflow correctly across phone, tablet and desktop screen sizes and orientations? | E19: Yes / Partial / No / N/A | F19: Device/browser test matrix results; analytics showing device mix. | G19: 3 | H19: Y | I19: Ensure the application is adaptive, so content and objects scale to the user's screen size and orientation, and test key tasks on the devices your users actually use. | J19: OMB M-23-22 (design pillar); WCAG 2.2 SC 1.3.4, 1.4.10 | K19: M-23-22 (2023); WCAG 2.2 | L19: Good practice | M19: All | P19: Partial | Q19: =IF(P19="Yes",Scoring!$C$6,IF(P19="Partial",Scoring!$C$7,IF(P19="No",Scoring!$C$8,""))) -> 0.5 | R19: =IF(Q19="",0,G19*Q19) -> 1.5 | S19: =IF(Q19="",0,G19) -> 3 | T19: =IF(OR(P19="Partial",P19="No"),I19,"") -> Ensure the application is adaptive, so content and objects scale to the user's screen size and orientation, and test key tasks on the devices your users actually use. | U19: =IF(Q19="",0,(1-Q19)*G19/SUMIFS($S$2:$S$97,$B$2:$B$97,B19)*INDEX(Scoring!$C$18:$C$27,MATCH(B19,Scoring!$B$18:$B$27,0))) -> 0.97826087 | V19: =IF(U19>0,U19+IF(AND(H19="Y",P19="No"),1000,0)+ROW()/100000,0) -> 0.97845087 | W19: GOV.UK: services that work on mobile | X19: https://www.gov.uk/service-manual/technology/working-with-mobile-technology
A20: UXD-02 | B20: Usability and design | C20: User research | D20: Has research with real users of this service (not proxies) informed its design or changes in the last 12 months? | E20: Yes / Partial / No / N/A | F20: Research reports, insights repository, decisions traced to research. | G20: 3 | H20: N | I20: Run regular user research with people who use the service, including those who struggle, and record how findings change the service. | J20: GOV.UK Service Standard point 1; AU DSS 2.0 criterion 2; Digital Service Design Standard | K20: GOV.UK SS (2019); AU DSS 2.0 | L20: Recommended (NZ) | M20: All | P20: Yes | Q20: =IF(P20="Yes",Scoring!$C$6,IF(P20="Partial",Scoring!$C$7,IF(P20="No",Scoring!$C$8,""))) -> 1 | R20: =IF(Q20="",0,G20*Q20) -> 3 | S20: =IF(Q20="",0,G20) -> 3 | T20: =IF(OR(P20="Partial",P20="No"),I20,"") | U20: =IF(Q20="",0,(1-Q20)*G20/SUMIFS($S$2:$S$97,$B$2:$B$97,B20)*INDEX(Scoring!$C$18:$C$27,MATCH(B20,Scoring!$B$18:$B$27,0))) -> 0 | V20: =IF(U20>0,U20+IF(AND(H20="Y",P20="No"),1000,0)+ROW()/100000,0) -> 0 | W20: GOV.UK: understand users and needs | X20: https://www.gov.uk/service-manual/service-standard/point-1-understand-user-needs
A21: UXD-03 | B21: Usability and design | C21: Usability testing | D21: Have the service's key tasks been usability tested with representative users, with task success and problem areas measured? | E21: Yes / Partial / No / N/A | F21: Usability test reports with task completion rates and severity-rated issues. | G21: 2 | H21: N | I21: Usability test the most important tasks with representative users at least annually and after significant change, and fix high-severity issues first. | J21: GOV.UK Service Standard point 4; ISO 9241-11 | K21: GOV.UK SS; ISO 9241-11:2018 | L21: Good practice | M21: All | P21: Partial | Q21: =IF(P21="Yes",Scoring!$C$6,IF(P21="Partial",Scoring!$C$7,IF(P21="No",Scoring!$C$8,""))) -> 0.5 | R21: =IF(Q21="",0,G21*Q21) -> 1 | S21: =IF(Q21="",0,G21) -> 2 | T21: =IF(OR(P21="Partial",P21="No"),I21,"") -> Usability test the most important tasks with representative users at least annually and after significant change, and fix high-severity issues first. | U21: =IF(Q21="",0,(1-Q21)*G21/SUMIFS($S$2:$S$97,$B$2:$B$97,B21)*INDEX(Scoring!$C$18:$C$27,MATCH(B21,Scoring!$B$18:$B$27,0))) -> 0.65217391 | V21: =IF(U21>0,U21+IF(AND(H21="Y",P21="No"),1000,0)+ROW()/100000,0) -> 0.65238391 | W21: GOV.UK: make the service simple | X21: https://www.gov.uk/service-manual/service-standard/point-4-make-the-service-simple-to-use
A22: UXD-04 | B22: Usability and design | C22: Heuristics | D22: Has the service been reviewed against recognised usability heuristics (for example Nielsen's 10 usability heuristics) in the last 12 months? | E22: Yes / Partial / No / N/A | F22: Heuristic review findings with severity ratings. | G22: 1 | H22: N | I22: Complete a heuristic review against Nielsen's 10 usability heuristics and add findings to the improvement backlog. | J22: Nielsen's 10 usability heuristics (NN/g) | K22: 1994, updated 2020 | L22: Good practice | M22: All | N22: Reuse heuristic names and concepts; write your own descriptions rather than copying NN/g text. | P22: Yes | Q22: =IF(P22="Yes",Scoring!$C$6,IF(P22="Partial",Scoring!$C$7,IF(P22="No",Scoring!$C$8,""))) -> 1 | R22: =IF(Q22="",0,G22*Q22) -> 1 | S22: =IF(Q22="",0,G22) -> 1 | T22: =IF(OR(P22="Partial",P22="No"),I22,"") | U22: =IF(Q22="",0,(1-Q22)*G22/SUMIFS($S$2:$S$97,$B$2:$B$97,B22)*INDEX(Scoring!$C$18:$C$27,MATCH(B22,Scoring!$B$18:$B$27,0))) -> 0 | V22: =IF(U22>0,U22+IF(AND(H22="Y",P22="No"),1000,0)+ROW()/100000,0) -> 0 | W22: NN/g: running a heuristic evaluation | X22: https://www.nngroup.com/articles/how-to-conduct-a-heuristic-evaluation/
A23: UXD-05 | B23: Usability and design | C23: Feedback | D23: Does the service always tell users what is happening - loading, saving, submitting - and give clear confirmation of what has been done and what happens next? | E23: Yes / Partial / No / N/A | F23: Screens for loading, success and confirmation states; confirmation messages/emails. | G23: 2 | H23: N | I23: Show clear progress and loading states, and give a confirmation page and message with a reference number and what happens next for every completed transaction. | J23: Nielsen heuristic 1 (visibility of system status) | L23: Good practice | M23: All | P23: Yes | Q23: =IF(P23="Yes",Scoring!$C$6,IF(P23="Partial",Scoring!$C$7,IF(P23="No",Scoring!$C$8,""))) -> 1 | R23: =IF(Q23="",0,G23*Q23) -> 2 | S23: =IF(Q23="",0,G23) -> 2 | T23: =IF(OR(P23="Partial",P23="No"),I23,"") | U23: =IF(Q23="",0,(1-Q23)*G23/SUMIFS($S$2:$S$97,$B$2:$B$97,B23)*INDEX(Scoring!$C$18:$C$27,MATCH(B23,Scoring!$B$18:$B$27,0))) -> 0 | V23: =IF(U23>0,U23+IF(AND(H23="Y",P23="No"),1000,0)+ROW()/100000,0) -> 0 | W23: NN/g: 10 usability heuristics | X23: https://www.nngroup.com/articles/ten-usability-heuristics/
A24: UXD-06 | B24: Usability and design | C24: Findability | D24: Can users find what they need - clear navigation, labels in users' language, and site search that returns relevant results? | E24: Yes / Partial / No / N/A | F24: Tree test or findability results; search analytics (top queries, zero-result searches). | G24: 2 | H24: N | I24: Structure navigation around user tasks, test it with users, and monitor search queries to improve labels and results. | J24: OMB M-23-22 (search pillar); Nielsen heuristic 2 | K24: M-23-22 | L24: Good practice | M24: All | P24: Partial | Q24: =IF(P24="Yes",Scoring!$C$6,IF(P24="Partial",Scoring!$C$7,IF(P24="No",Scoring!$C$8,""))) -> 0.5 | R24: =IF(Q24="",0,G24*Q24) -> 1 | S24: =IF(Q24="",0,G24) -> 2 | T24: =IF(OR(P24="Partial",P24="No"),I24,"") -> Structure navigation around user tasks, test it with users, and monitor search queries to improve labels and results. | U24: =IF(Q24="",0,(1-Q24)*G24/SUMIFS($S$2:$S$97,$B$2:$B$97,B24)*INDEX(Scoring!$C$18:$C$27,MATCH(B24,Scoring!$B$18:$B$27,0))) -> 0.65217391 | V24: =IF(U24>0,U24+IF(AND(H24="Y",P24="No"),1000,0)+ROW()/100000,0) -> 0.65241391 | W24: NN/g: 10 usability heuristics | X24: https://www.nngroup.com/articles/ten-usability-heuristics/
A25: UXD-07 | B25: Usability and design | C25: Errors | D25: Does the service prevent errors and help users recover - confirming destructive actions, saving progress, and explaining errors in plain language? | E25: Yes / Partial / No / N/A | F25: Error message inventory; save-and-return feature; confirmation patterns. | G25: 2 | H25: N | I25: Prevent common errors with good defaults and validation, let users save and return to long forms, and write error messages that say what went wrong and how to fix it. | J25: Nielsen heuristics 3, 5 and 9 | L25: Good practice | M25: Transactional | P25: Yes | Q25: =IF(P25="Yes",Scoring!$C$6,IF(P25="Partial",Scoring!$C$7,IF(P25="No",Scoring!$C$8,""))) -> 1 | R25: =IF(Q25="",0,G25*Q25) -> 2 | S25: =IF(Q25="",0,G25) -> 2 | T25: =IF(OR(P25="Partial",P25="No"),I25,"") | U25: =IF(Q25="",0,(1-Q25)*G25/SUMIFS($S$2:$S$97,$B$2:$B$97,B25)*INDEX(Scoring!$C$18:$C$27,MATCH(B25,Scoring!$B$18:$B$27,0))) -> 0 | V25: =IF(U25>0,U25+IF(AND(H25="Y",P25="No"),1000,0)+ROW()/100000,0) -> 0 | W25: NN/g: 10 usability heuristics | X25: https://www.nngroup.com/articles/ten-usability-heuristics/
A26: UXD-08 | B26: Usability and design | C26: Design system | D26: Is the service built using an established design system or pattern library (organisation or shared government) rather than one-off components? | E26: Yes / Partial / No / N/A | F26: Design system name and version; component usage audit. | G26: 2 | H26: N | I26: Use and contribute to a shared design system so components are tested, accessible and consistent across the organisation's services. | J26: GOV.UK Service Standard point 13; AU DSS 2.0 criterion 6 (don't reinvent the wheel) | L26: Good practice | M26: All | P26: No | Q26: =IF(P26="Yes",Scoring!$C$6,IF(P26="Partial",Scoring!$C$7,IF(P26="No",Scoring!$C$8,""))) -> 0 | R26: =IF(Q26="",0,G26*Q26) -> 0 | S26: =IF(Q26="",0,G26) -> 2 | T26: =IF(OR(P26="Partial",P26="No"),I26,"") -> Use and contribute to a shared design system so components are tested, accessible and consistent across the organisation's services. | U26: =IF(Q26="",0,(1-Q26)*G26/SUMIFS($S$2:$S$97,$B$2:$B$97,B26)*INDEX(Scoring!$C$18:$C$27,MATCH(B26,Scoring!$B$18:$B$27,0))) -> 1.3043478 | V26: =IF(U26>0,U26+IF(AND(H26="Y",P26="No"),1000,0)+ROW()/100000,0) -> 1.3046078 | W26: GOV.UK: reuse common components, patterns | X26: https://www.gov.uk/service-manual/service-standard/point-13-use-common-standards-components-patterns
A27: UXD-09 | B27: Usability and design | C27: Whole journey | D27: Has the end-to-end user journey been mapped, including offline steps, other agencies and hand-offs, and are pain points across channels addressed? | E27: Yes / Partial / No / N/A | F27: Journey or service blueprint; list of cross-channel issues and actions. | G27: 2 | H27: N | I27: Map the full journey across channels and organisations and design the digital service to work smoothly with the steps before and after it. | J27: GOV.UK Service Standard points 2 and 3; AU DSS 2.0 criterion 4 (connect services) | L27: Good practice | M27: All | P27: Yes | Q27: =IF(P27="Yes",Scoring!$C$6,IF(P27="Partial",Scoring!$C$7,IF(P27="No",Scoring!$C$8,""))) -> 1 | R27: =IF(Q27="",0,G27*Q27) -> 2 | S27: =IF(Q27="",0,G27) -> 2 | T27: =IF(OR(P27="Partial",P27="No"),I27,"") | U27: =IF(Q27="",0,(1-Q27)*G27/SUMIFS($S$2:$S$97,$B$2:$B$97,B27)*INDEX(Scoring!$C$18:$C$27,MATCH(B27,Scoring!$B$18:$B$27,0))) -> 0 | V27: =IF(U27>0,U27+IF(AND(H27="Y",P27="No"),1000,0)+ROW()/100000,0) -> 0 | W27: GOV.UK: solve a whole problem | X27: https://www.gov.uk/service-manual/service-standard/point-2-solve-a-whole-problem
A28: UXD-10 | B28: Usability and design | C28: Performance | D28: Do pages load and respond quickly on typical NZ mobile connections and devices, with front-end performance (for example Core Web Vitals) monitored? | E28: Yes / Partial / No / N/A | F28: Lighthouse or real-user monitoring results for key pages. | G28: 2 | H28: N | I28: Set performance budgets, monitor real-user performance (for example Core Web Vitals) and optimise key pages for mobile devices and slower connections. | J28: Google Core Web Vitals; OMB M-23-22 | L28: Good practice | M28: All | P28: Yes | Q28: =IF(P28="Yes",Scoring!$C$6,IF(P28="Partial",Scoring!$C$7,IF(P28="No",Scoring!$C$8,""))) -> 1 | R28: =IF(Q28="",0,G28*Q28) -> 2 | S28: =IF(Q28="",0,G28) -> 2 | T28: =IF(OR(P28="Partial",P28="No"),I28,"") | U28: =IF(Q28="",0,(1-Q28)*G28/SUMIFS($S$2:$S$97,$B$2:$B$97,B28)*INDEX(Scoring!$C$18:$C$27,MATCH(B28,Scoring!$B$18:$B$27,0))) -> 0 | V28: =IF(U28>0,U28+IF(AND(H28="Y",P28="No"),1000,0)+ROW()/100000,0) -> 0 | W28: Google: Core Web Vitals | X28: https://web.dev/articles/vitals
A29: UXD-11 | B29: Usability and design | C29: Compatibility | D29: Is there a defined browser, device and assistive technology support policy, and is the service tested against it before release? | E29: Yes / Partial / No / N/A | F29: Support policy; release test evidence. | G29: 1 | H29: N | I29: Define which browsers, devices and assistive technologies are supported based on user data, and test against that list before each release. | J29: GOV.UK Service Manual (designing for different browsers and devices) | L29: Good practice | M29: All | P29: Yes | Q29: =IF(P29="Yes",Scoring!$C$6,IF(P29="Partial",Scoring!$C$7,IF(P29="No",Scoring!$C$8,""))) -> 1 | R29: =IF(Q29="",0,G29*Q29) -> 1 | S29: =IF(Q29="",0,G29) -> 1 | T29: =IF(OR(P29="Partial",P29="No"),I29,"") | U29: =IF(Q29="",0,(1-Q29)*G29/SUMIFS($S$2:$S$97,$B$2:$B$97,B29)*INDEX(Scoring!$C$18:$C$27,MATCH(B29,Scoring!$B$18:$B$27,0))) -> 0 | V29: =IF(U29>0,U29+IF(AND(H29="Y",P29="No"),1000,0)+ROW()/100000,0) -> 0 | W29: GOV.UK: browser and device testing | X29: https://www.gov.uk/service-manual/technology/designing-for-different-browsers-and-devices
A30: UXD-12 | B30: Usability and design | C30: Data minimisation | D30: Does the service only ask for information it needs, and reuse information the agency already holds where lawful (so users don't repeat themselves)? | E30: Yes / Partial / No / N/A | F30: Field-by-field justification; data reuse arrangements. | G30: 1 | H30: N | I30: Remove questions that aren't needed, explain why information is asked for, and reuse information already held where the law allows. | J30: Privacy Act 2020 IPP 1; AU DSS 2.0 criterion 4 | K30: Privacy Act 2020 | L30: Recommended (NZ) | M30: Transactional | P30: Partial | Q30: =IF(P30="Yes",Scoring!$C$6,IF(P30="Partial",Scoring!$C$7,IF(P30="No",Scoring!$C$8,""))) -> 0.5 | R30: =IF(Q30="",0,G30*Q30) -> 0.5 | S30: =IF(Q30="",0,G30) -> 1 | T30: =IF(OR(P30="Partial",P30="No"),I30,"") -> Remove questions that aren't needed, explain why information is asked for, and reuse information already held where the law allows. | U30: =IF(Q30="",0,(1-Q30)*G30/SUMIFS($S$2:$S$97,$B$2:$B$97,B30)*INDEX(Scoring!$C$18:$C$27,MATCH(B30,Scoring!$B$18:$B$27,0))) -> 0.32608696 | V30: =IF(U30>0,U30+IF(AND(H30="Y",P30="No"),1000,0)+ROW()/100000,0) -> 0.32638696 | W30: Privacy Act 2020 | X30: https://www.legislation.govt.nz/act/public/2020/31/en/latest/
A31: CON-01 | B31: Content and tone of voice | C31: Plain language | D31: Is content written in plain language appropriate to the intended audience, and has it been checked (for example readability testing or user testing)? | E31: Yes / Partial / No / N/A | F31: Content review results; readability scores; plain language checks. | G31: 3 | H31: N | I31: Write and review all public content in plain language, test it with users, and follow the agency's Plain Language Act processes. | J31: Plain Language Act 2022 | K31: Plain Language Act 2022 | L31: Mandatory (NZ) | M31: Public-facing | N31: Applies to public service agencies and Crown agents. A Plain Language Act Repeal Bill was introduced in 2025 (first reading 1 Apr 2025) and had not been enacted at 24 Oct 2026. If the Act is repealed, change NZ status to Good practice and keep the criterion. | P31: Yes | Q31: =IF(P31="Yes",Scoring!$C$6,IF(P31="Partial",Scoring!$C$7,IF(P31="No",Scoring!$C$8,""))) -> 1 | R31: =IF(Q31="",0,G31*Q31) -> 3 | S31: =IF(Q31="",0,G31) -> 3 | T31: =IF(OR(P31="Partial",P31="No"),I31,"") | U31: =IF(Q31="",0,(1-Q31)*G31/SUMIFS($S$2:$S$97,$B$2:$B$97,B31)*INDEX(Scoring!$C$18:$C$27,MATCH(B31,Scoring!$B$18:$B$27,0))) -> 0 | V31: =IF(U31>0,U31+IF(AND(H31="Y",P31="No"),1000,0)+ROW()/100000,0) -> 0 | W31: Plain Language Act 2022 | X31: https://www.legislation.govt.nz/act/public/2022/0054/latest/whole.html
A32: CON-02 | B32: Content and tone of voice | C32: Tone of voice | D32: Does the organisation have tone of voice guidelines, and does the service's content follow them? | E32: Yes / Partial / No / N/A | F32: Tone of voice guidelines; content review against them. | G32: 2 | H32: N | I32: Apply the organisation's tone of voice guidelines to all service content, including error messages, emails and letters, and review content against them. | J32: Organisation brand and tone of voice guidelines | K32: Organisation-specific | L32: Good practice | M32: All | N32: Organisation supplies its own guideline reference. | P32: No | Q32: =IF(P32="Yes",Scoring!$C$6,IF(P32="Partial",Scoring!$C$7,IF(P32="No",Scoring!$C$8,""))) -> 0 | R32: =IF(Q32="",0,G32*Q32) -> 0 | S32: =IF(Q32="",0,G32) -> 2 | T32: =IF(OR(P32="Partial",P32="No"),I32,"") -> Apply the organisation's tone of voice guidelines to all service content, including error messages, emails and letters, and review content against them. | U32: =IF(Q32="",0,(1-Q32)*G32/SUMIFS($S$2:$S$97,$B$2:$B$97,B32)*INDEX(Scoring!$C$18:$C$27,MATCH(B32,Scoring!$B$18:$B$27,0))) -> 1.3333333 | V32: =IF(U32>0,U32+IF(AND(H32="Y",P32="No"),1000,0)+ROW()/100000,0) -> 1.3336533 | W32: Use your organisation's tone of voice
A33: CON-03 | B33: Content and tone of voice | C33: Style | D33: Is content consistent with a content style guide (NZ English, terminology, dates, numbers, capitalisation)? | E33: Yes / Partial / No / N/A | F33: Style guide reference; content audit results. | G33: 1 | H33: N | I33: Adopt a content style guide (organisation or NZ Government) and apply it consistently, including a glossary of service terms. | J33: Organisation style guide; NZ Government content guidance (Digital.govt.nz) | L33: Good practice | M33: All | P33: Yes | Q33: =IF(P33="Yes",Scoring!$C$6,IF(P33="Partial",Scoring!$C$7,IF(P33="No",Scoring!$C$8,""))) -> 1 | R33: =IF(Q33="",0,G33*Q33) -> 1 | S33: =IF(Q33="",0,G33) -> 1 | T33: =IF(OR(P33="Partial",P33="No"),I33,"") | U33: =IF(Q33="",0,(1-Q33)*G33/SUMIFS($S$2:$S$97,$B$2:$B$97,B33)*INDEX(Scoring!$C$18:$C$27,MATCH(B33,Scoring!$B$18:$B$27,0))) -> 0 | V33: =IF(U33>0,U33+IF(AND(H33="Y",P33="No"),1000,0)+ROW()/100000,0) -> 0 | W33: Use your organisation's style guide
A34: CON-04 | B34: Content and tone of voice | C34: Accuracy | D34: Is service content authoritative and current, with no duplicate or conflicting information across the agency's channels? | E34: Yes / Partial / No / N/A | F34: Content inventory; duplicate content review. | G34: 2 | H34: N | I34: Keep one authoritative source for each piece of service information, remove or redirect duplicates, and check consistency with call centre scripts and printed material. | J34: OMB M-23-22 (content pillar) | L34: Good practice | M34: All | P34: Partial | Q34: =IF(P34="Yes",Scoring!$C$6,IF(P34="Partial",Scoring!$C$7,IF(P34="No",Scoring!$C$8,""))) -> 0.5 | R34: =IF(Q34="",0,G34*Q34) -> 1 | S34: =IF(Q34="",0,G34) -> 2 | T34: =IF(OR(P34="Partial",P34="No"),I34,"") -> Keep one authoritative source for each piece of service information, remove or redirect duplicates, and check consistency with call centre scripts and printed material. | U34: =IF(Q34="",0,(1-Q34)*G34/SUMIFS($S$2:$S$97,$B$2:$B$97,B34)*INDEX(Scoring!$C$18:$C$27,MATCH(B34,Scoring!$B$18:$B$27,0))) -> 0.66666667 | V34: =IF(U34>0,U34+IF(AND(H34="Y",P34="No"),1000,0)+ROW()/100000,0) -> 0.66700667 | W34: US digital-first experience memo | X34: https://www.whitehouse.gov/wp-content/uploads/2023/09/M-23-22-Delivering-a-Digital-First-Public-Experience.pdf
A35: CON-05 | B35: Content and tone of voice | C35: Links and labels | D35: Are buttons, links and labels clear and specific (no 'click here'), and has microcopy been tested with users? | E35: Yes / Partial / No / N/A | F35: Audit findings for SC 2.4.4; microcopy test results. | G35: 1 | H35: N | I35: Write descriptive link text and button labels that make sense out of context, and test key microcopy with users. | J35: WCAG 2.2 SC 2.4.4, 2.4.6 | K35: WCAG 2.2 A/AA | L35: Mandatory (NZ) | M35: All | P35: Yes | Q35: =IF(P35="Yes",Scoring!$C$6,IF(P35="Partial",Scoring!$C$7,IF(P35="No",Scoring!$C$8,""))) -> 1 | R35: =IF(Q35="",0,G35*Q35) -> 1 | S35: =IF(Q35="",0,G35) -> 1 | T35: =IF(OR(P35="Partial",P35="No"),I35,"") | U35: =IF(Q35="",0,(1-Q35)*G35/SUMIFS($S$2:$S$97,$B$2:$B$97,B35)*INDEX(Scoring!$C$18:$C$27,MATCH(B35,Scoring!$B$18:$B$27,0))) -> 0 | V35: =IF(U35>0,U35+IF(AND(H35="Y",P35="No"),1000,0)+ROW()/100000,0) -> 0 | W35: WCAG 2.2 quick reference | X35: https://www.w3.org/WAI/WCAG22/quickref/
A36: CON-06 | B36: Content and tone of voice | C36: Te reo Māori | D36: Has the service considered te reo Māori - correct use and display of macrons, bilingual names and content where appropriate? | E36: Yes / Partial / No / N/A | F36: Te reo Māori approach; macron rendering test; reviewed translations. | G36: 1 | H36: N | I36: Agree a te reo Māori approach for the service, ensure macrons display and are searchable, and have te reo content reviewed by a qualified speaker. | J36: Te Ture mō Te Reo Māori 2016 (Māori Language Act); Digital Service Design Standard | L36: Recommended (NZ) | M36: All | P36: Yes | Q36: =IF(P36="Yes",Scoring!$C$6,IF(P36="Partial",Scoring!$C$7,IF(P36="No",Scoring!$C$8,""))) -> 1 | R36: =IF(Q36="",0,G36*Q36) -> 1 | S36: =IF(Q36="",0,G36) -> 1 | T36: =IF(OR(P36="Partial",P36="No"),I36,"") | U36: =IF(Q36="",0,(1-Q36)*G36/SUMIFS($S$2:$S$97,$B$2:$B$97,B36)*INDEX(Scoring!$C$18:$C$27,MATCH(B36,Scoring!$B$18:$B$27,0))) -> 0 | V36: =IF(U36>0,U36+IF(AND(H36="Y",P36="No"),1000,0)+ROW()/100000,0) -> 0 | W36: Māori Language Act 2016 | X36: https://www.legislation.govt.nz/act/public/2016/0017/latest/DLM6174566.html
A37: CON-07 | B37: Content and tone of voice | C37: Alternative formats | D37: Is key service information available in alternative formats where needed (for example Easy Read, NZ Sign Language, large print, audio, Braille)? | E37: Yes / Partial / No / N/A | F37: List of alternative formats; process for requesting them. | G37: 1 | H37: N | I37: Provide key information in alternative formats and offer a simple way to request others. | J37: Accessibility Charter (MSD); draft Digital Accessibility Standard | K37: DAS draft (Jul 2026) | L37: Recommended (NZ) | M37: Public-facing | P37: Partial | Q37: =IF(P37="Yes",Scoring!$C$6,IF(P37="Partial",Scoring!$C$7,IF(P37="No",Scoring!$C$8,""))) -> 0.5 | R37: =IF(Q37="",0,G37*Q37) -> 0.5 | S37: =IF(Q37="",0,G37) -> 1 | T37: =IF(OR(P37="Partial",P37="No"),I37,"") -> Provide key information in alternative formats and offer a simple way to request others. | U37: =IF(Q37="",0,(1-Q37)*G37/SUMIFS($S$2:$S$97,$B$2:$B$97,B37)*INDEX(Scoring!$C$18:$C$27,MATCH(B37,Scoring!$B$18:$B$27,0))) -> 0.33333333 | V37: =IF(U37>0,U37+IF(AND(H37="Y",P37="No"),1000,0)+ROW()/100000,0) -> 0.33370333 | W37: MSD Accessibility Charter | X37: https://www.msd.govt.nz/about-msd-and-our-work/work-programmes/accessibility/accessibility-charter/the-charter.html
A38: CON-08 | B38: Content and tone of voice | C38: Languages | D38: Have the language needs of the service's users been identified, with translated content provided where needed? | E38: Yes / Partial / No / N/A | F38: User language data; translated content inventory. | G38: 1 | H38: N | I38: Use research and demographic data to identify language needs and translate key content, using professional translators. | J38: Digital Service Design Standard | L38: Good practice | M38: Public-facing | P38: Yes | Q38: =IF(P38="Yes",Scoring!$C$6,IF(P38="Partial",Scoring!$C$7,IF(P38="No",Scoring!$C$8,""))) -> 1 | R38: =IF(Q38="",0,G38*Q38) -> 1 | S38: =IF(Q38="",0,G38) -> 1 | T38: =IF(OR(P38="Partial",P38="No"),I38,"") | U38: =IF(Q38="",0,(1-Q38)*G38/SUMIFS($S$2:$S$97,$B$2:$B$97,B38)*INDEX(Scoring!$C$18:$C$27,MATCH(B38,Scoring!$B$18:$B$27,0))) -> 0 | V38: =IF(U38>0,U38+IF(AND(H38="Y",P38="No"),1000,0)+ROW()/100000,0) -> 0 | W38: NZ Digital Service Design principles | X38: https://www.digital.govt.nz/standards-and-guidance/digital-service-design-standard/principles
A39: BRD-01 | B39: Brand and visual consistency | C39: Brand guidelines | D39: Does the service apply the organisation's brand guidelines - logos, font types, colour palette, iconography and styling? | E39: Yes / Partial / No / N/A | F39: Brand guideline reference; design review against guidelines. | G39: 3 | H39: N | I39: Apply the organisation's brand guidelines, including font types, colour palette and styling, to minimise experience inconsistency across applications. | J39: Organisation brand guidelines; OMB M-23-22 (branding pillar) | K39: Organisation-specific | L39: Good practice | M39: All | P39: No | Q39: =IF(P39="Yes",Scoring!$C$6,IF(P39="Partial",Scoring!$C$7,IF(P39="No",Scoring!$C$8,""))) -> 0 | R39: =IF(Q39="",0,G39*Q39) -> 0 | S39: =IF(Q39="",0,G39) -> 3 | T39: =IF(OR(P39="Partial",P39="No"),I39,"") -> Apply the organisation's brand guidelines, including font types, colour palette and styling, to minimise experience inconsistency across applications. | U39: =IF(Q39="",0,(1-Q39)*G39/SUMIFS($S$2:$S$97,$B$2:$B$97,B39)*INDEX(Scoring!$C$18:$C$27,MATCH(B39,Scoring!$B$18:$B$27,0))) -> 1.5 | V39: =IF(U39>0,U39+IF(AND(H39="Y",P39="No"),1000,0)+ROW()/100000,0) -> 1.50039 | W39: Use your organisation's brand guidelines
A40: BRD-02 | B40: Brand and visual consistency | C40: Government identity | D40: Does the website's home page clearly identify it as a NZ Government site and link to Govt.nz using the recommended NZ Government logo markup? | E40: Yes / Partial / No / N/A | F40: Screenshot of home page; markup check. | G40: 2 | H40: N | I40: Add the NZ Government identity link to Govt.nz on the home page using the recommended accessible logo markup. | J40: Web Usability Standard 1.4 s2.2 (Government identity); NZ government logo markup guidance | K40: WUS 1.4 (from 17 Mar 2025) | L40: Mandatory (NZ) | M40: Public-facing | N40: Web Usability Standard requirements are expected to become guidance within the updated Digital Service Design Standard. | P40: Yes | Q40: =IF(P40="Yes",Scoring!$C$6,IF(P40="Partial",Scoring!$C$7,IF(P40="No",Scoring!$C$8,""))) -> 1 | R40: =IF(Q40="",0,G40*Q40) -> 2 | S40: =IF(Q40="",0,G40) -> 2 | T40: =IF(OR(P40="Partial",P40="No"),I40,"") | U40: =IF(Q40="",0,(1-Q40)*G40/SUMIFS($S$2:$S$97,$B$2:$B$97,B40)*INDEX(Scoring!$C$18:$C$27,MATCH(B40,Scoring!$B$18:$B$27,0))) -> 0 | V40: =IF(U40>0,U40+IF(AND(H40="Y",P40="No"),1000,0)+ROW()/100000,0) -> 0 | W40: NZ government logo markup guidance | X40: https://www.digital.govt.nz/standards-and-guidance/design-and-ux/usability/nz-government-logo-markup
...

Sheet Scoring
B1: Scoring - detailed criteria
B2: Yellow cells are editable. Results use the Test answer column on the Criteria tab. Earned/Available are weighted (weight x answer points).
B4: Parameters
B5: Answer | C5: Points
B6: Yes | C6: 1
B7: Partial | C7: 0.5
B8: No | C8: 0
B10: Overall score cap when any critical criterion is 'No' | C10: 60 | E10: Proposed defaults - validate with test assessments before use.
B11: Rating threshold - Healthy (score at or above) | C11: 85
B12: Rating threshold - Good, with gaps (at or above) | C12: 70
B13: Rating threshold - Needs attention (at or above); below = At risk | C13: 50
B16: Category results
B17: Category | C17: Points (of 100) | D17: Criteria | E17: Earned | F17: Available | G17: Category % | H17: Score | I17: What good looks like
B18: Accessibility | C18: 20 | D18: =COUNTIF(Criteria!$B$2:$B$97,B18) -> 17 | E18: =SUMIFS(Criteria!$R$2:$R$97,Criteria!$B$2:$B$97,B18) -> 27 | F18: =SUMIFS(Criteria!$S$2:$S$97,Criteria!$B$2:$B$97,B18) -> 33 | G18: =IF(F18=0,"",E18/F18) -> 0.81818182 | H18: =IF(F18=0,"",G18*C18) -> 16.363636 | I18: Disabled people, including blind and low vision users, can perceive, operate and complete the service.
B19: Usability and design | C19: 15 | D19: =COUNTIF(Criteria!$B$2:$B$97,B19) -> 12 | E19: =SUMIFS(Criteria!$R$2:$R$97,Criteria!$B$2:$B$97,B19) -> 17 | F19: =SUMIFS(Criteria!$S$2:$S$97,Criteria!$B$2:$B$97,B19) -> 23 | G19: =IF(F19=0,"",E19/F19) -> 0.73913043 | H19: =IF(F19=0,"",G19*C19) -> 11.086957 | I19: The service is easy to use, works across devices and is designed around user needs.
B20: Content and tone of voice | C20: 8 | D20: =COUNTIF(Criteria!$B$2:$B$97,B20) -> 8 | E20: =SUMIFS(Criteria!$R$2:$R$97,Criteria!$B$2:$B$97,B20) -> 8.5 | F20: =SUMIFS(Criteria!$S$2:$S$97,Criteria!$B$2:$B$97,B20) -> 12 | G20: =IF(F20=0,"",E20/F20) -> 0.70833333 | H20: =IF(F20=0,"",G20*C20) -> 5.6666667 | I20: Content is plain, accurate, consistent and written in the organisation's voice.
B21: Brand and visual consistency | C21: 6 | D21: =COUNTIF(Criteria!$B$2:$B$97,B21) -> 6 | E21: =SUMIFS(Criteria!$R$2:$R$97,Criteria!$B$2:$B$97,B21) -> 8 | F21: =SUMIFS(Criteria!$S$2:$S$97,Criteria!$B$2:$B$97,B21) -> 12 | G21: =IF(F21=0,"",E21/F21) -> 0.66666667 | H21: =IF(F21=0,"",G21*C21) -> 4 | I21: The service looks and feels consistent with the organisation and NZ Government identity.
B22: Security and privacy | C22: 14 | D22: =COUNTIF(Criteria!$B$2:$B$97,B22) -> 11 | E22: =SUMIFS(Criteria!$R$2:$R$97,Criteria!$B$2:$B$97,B22) -> 18.5 | F22: =SUMIFS(Criteria!$S$2:$S$97,Criteria!$B$2:$B$97,B22) -> 24 | G22: =IF(F22=0,"",E22/F22) -> 0.77083333 | H22: =IF(F22=0,"",G22*C22) -> 10.791667 | I22: The service protects users and their information and meets NZ security and privacy obligations.
B23: Reliability, observability and service levels | C23: 13 | D23: =COUNTIF(Criteria!$B$2:$B$97,B23) -> 11 | E23: =SUMIFS(Criteria!$R$2:$R$97,Criteria!$B$2:$B$97,B23) -> 14.5 | F23: =SUMIFS(Criteria!$S$2:$S$97,Criteria!$B$2:$B$97,B23) -> 21 | G23: =IF(F23=0,"",E23/F23) -> 0.69047619 | H23: =IF(F23=0,"",G23*C23) -> 8.9761905 | I23: The service is available, monitored, and issues are found and fixed quickly.
B24: Support and contact channels | C24: 8 | D24: =COUNTIF(Criteria!$B$2:$B$97,B24) -> 7 | E24: =SUMIFS(Criteria!$R$2:$R$97,Criteria!$B$2:$B$97,B24) -> 10.5 | F24: =SUMIFS(Criteria!$S$2:$S$97,Criteria!$B$2:$B$97,B24) -> 14 | G24: =IF(F24=0,"",E24/F24) -> 0.75 | H24: =IF(F24=0,"",G24*C24) -> 6 | I24: People can get help, in the channel that works for them, when they need it.
B25: Legal and regulatory | C25: 6 | D25: =COUNTIF(Criteria!$B$2:$B$97,B25) -> 9 | E25: =SUMIFS(Criteria!$R$2:$R$97,Criteria!$B$2:$B$97,B25) -> 9 | F25: =SUMIFS(Criteria!$S$2:$S$97,Criteria!$B$2:$B$97,B25) -> 13 | G25: =IF(F25=0,"",E25/F25) -> 0.69230769 | H25: =IF(F25=0,"",G25*C25) -> 4.1538462 | I25: The service meets NZ legal and public sector obligations about access to services and information.
B26: Content management and governance | C26: 5 | D26: =COUNTIF(Criteria!$B$2:$B$97,B26) -> 8 | E26: =SUMIFS(Criteria!$R$2:$R$97,Criteria!$B$2:$B$97,B26) -> 12 | F26: =SUMIFS(Criteria!$S$2:$S$97,Criteria!$B$2:$B$97,B26) -> 16 | G26: =IF(F26=0,"",E26/F26) -> 0.75 | H26: =IF(F26=0,"",G26*C26) -> 3.75 | I26: The service and its content have clear ownership, workflows and ongoing funding.
B27: Measurement and continuous improvement | C27: 5 | D27: =COUNTIF(Criteria!$B$2:$B$97,B27) -> 7 | E27: =SUMIFS(Criteria!$R$2:$R$97,Criteria!$B$2:$B$97,B27) -> 8.5 | F27: =SUMIFS(Criteria!$S$2:$S$97,Criteria!$B$2:$B$97,B27) -> 14 | G27: =IF(F27=0,"",E27/F27) -> 0.60714286 | H27: =IF(F27=0,"",G27*C27) -> 3.0357143 | I27: Performance and satisfaction are measured and used to improve the service.
B28: Total | C28: =SUM(C18:C27) -> 100 | D28: =SUM(D18:D27) -> 96 | I28: =IF(C28=100,"Category points total 100 - OK","CHECK: category points must total 100") -> Category points total 100 - OK
B30: Overall result
B31: Raw score (out of 100, rescaled for N/A categories) | C31: =IF(SUMIFS(C18:C27,F18:F27,">0")=0,"",SUM(H18:H27)/SUMIFS(C18:C27,F18:F27,">0")*100) -> 73.824677
B32: Critical criteria answered 'No' | C32: =COUNTIFS(Criteria!$H$2:$H$97,"Y",Criteria!$P$2:$P$97,"No") -> 0
B33: Final score (after critical cap) | C33: =IF(C31="","",IF(C32>0,MIN(C31,C10),C31)) -> 73.824677
B34: Rating | C34: =IF(C33="","",IF(C33>=C11,"Healthy",IF(C33>=C12,"Good, with gaps",IF(C33>=C13,"Needs attention","At risk")))) -> Good, with gaps
